[2024-03-31 01:43:33,313: INFO: main: welcome to my custom log]
[2024-03-31 03:06:37,103: INFO: main: >>>>>> stage Data Ingestion stage started <<<<<<]
[2024-03-31 03:06:37,112: INFO: common: yaml file: config\config.yaml loaded successfully]
[2024-03-31 03:06:37,112: ERROR: main: yaml file is empty]
Traceback (most recent call last):
  File "c:\users\rathu\desktop\insurance_premium-prediction\src\Insurance_prediction\utils\common.py", line 33, in read_yaml
    return ConfigBox(content)
  File "box\box.py", line 259, in box.box.Box.__init__
box.exceptions.BoxValueError: First argument must be mapping or iterable

During handling of the above exception, another exception occurred:

Traceback (most recent call last):
  File "C:\Users\rathu\Desktop\Insurance_premium-prediction\main.py", line 8, in <module>
    data_ingestion.main()
  File "c:\users\rathu\desktop\insurance_premium-prediction\src\Insurance_prediction\pipeline\stage_01_data_ingestion.py", line 13, in main
    config = ConfigurationManager()
  File "c:\users\rathu\desktop\insurance_premium-prediction\src\Insurance_prediction\config\configuration.py", line 13, in __init__
    self.config = read_yaml(config_filepath)
  File "C:\Users\rathu\anaconda3\lib\site-packages\ensure\main.py", line 849, in __call__
    return_val = self.f(*args, **kwargs)
  File "c:\users\rathu\desktop\insurance_premium-prediction\src\Insurance_prediction\utils\common.py", line 35, in read_yaml
    raise ValueError("yaml file is empty")
ValueError: yaml file is empty
[2024-03-31 03:10:04,508: INFO: main: >>>>>> stage Data Ingestion stage started <<<<<<]
[2024-03-31 03:10:04,545: INFO: common: yaml file: config\config.yaml loaded successfully]
[2024-03-31 03:10:04,558: INFO: common: yaml file: params.yaml loaded successfully]
[2024-03-31 03:10:04,558: ERROR: main: yaml file is empty]
Traceback (most recent call last):
  File "c:\users\rathu\desktop\insurance_premium-prediction\src\Insurance_prediction\utils\common.py", line 33, in read_yaml
    return ConfigBox(content)
  File "box\box.py", line 247, in box.box.Box.__init__
box.exceptions.BoxValueError: Cannot extrapolate Box from string

During handling of the above exception, another exception occurred:

Traceback (most recent call last):
  File "C:\Users\rathu\Desktop\Insurance_premium-prediction\main.py", line 8, in <module>
    data_ingestion.main()
  File "c:\users\rathu\desktop\insurance_premium-prediction\src\Insurance_prediction\pipeline\stage_01_data_ingestion.py", line 13, in main
    config = ConfigurationManager()
  File "c:\users\rathu\desktop\insurance_premium-prediction\src\Insurance_prediction\config\configuration.py", line 14, in __init__
    self.params = read_yaml(params_filepath)
  File "C:\Users\rathu\anaconda3\lib\site-packages\ensure\main.py", line 849, in __call__
    return_val = self.f(*args, **kwargs)
  File "c:\users\rathu\desktop\insurance_premium-prediction\src\Insurance_prediction\utils\common.py", line 35, in read_yaml
    raise ValueError("yaml file is empty")
ValueError: yaml file is empty
[2024-03-31 03:13:22,988: INFO: main: >>>>>> stage Data Ingestion stage started <<<<<<]
[2024-03-31 03:13:22,992: INFO: common: yaml file: config\config.yaml loaded successfully]
[2024-03-31 03:13:23,000: INFO: common: yaml file: params.yaml loaded successfully]
[2024-03-31 03:13:23,043: INFO: common: created directory at: artifacts]
[2024-03-31 03:13:23,043: INFO: common: created directory at: artifacts/data_ingestion]
[2024-03-31 03:13:23,623: INFO: data_ingestion: artifacts/data_ingestion/data.zip download! with following info: 
Server: GitHub.com
Date: Sat, 30 Mar 2024 21:43:23 GMT
Content-Type: text/html; charset=utf-8
Vary: X-PJAX, X-PJAX-Container, Turbo-Visit, Turbo-Frame, Accept-Encoding, Accept, X-Requested-With
ETag: W/"07ad957c4a30850eb6f6265f525c1a86"
Cache-Control: max-age=0, private, must-revalidate
Strict-Transport-Security: max-age=31536000; includeSubdomains; preload
X-Frame-Options: deny
X-Content-Type-Options: nosniff
X-XSS-Protection: 0
Referrer-Policy: no-referrer-when-downgrade
Content-Security-Policy: default-src 'none'; base-uri 'self'; child-src github.com/assets-cdn/worker/ gist.github.com/assets-cdn/worker/; connect-src 'self' uploads.github.com www.githubstatus.com collector.github.com raw.githubusercontent.com api.github.com github-cloud.s3.amazonaws.com github-production-repository-file-5c1aeb.s3.amazonaws.com github-production-upload-manifest-file-7fdce7.s3.amazonaws.com github-production-user-asset-6210df.s3.amazonaws.com api.githubcopilot.com objects-origin.githubusercontent.com *.actions.githubusercontent.com wss://*.actions.githubusercontent.com productionresultssa0.blob.core.windows.net/ productionresultssa1.blob.core.windows.net/ productionresultssa2.blob.core.windows.net/ productionresultssa3.blob.core.windows.net/ productionresultssa4.blob.core.windows.net/ productionresultssa5.blob.core.windows.net/ productionresultssa6.blob.core.windows.net/ productionresultssa7.blob.core.windows.net/ productionresultssa8.blob.core.windows.net/ productionresultssa9.blob.core.windows.net/ productionresultssa10.blob.core.windows.net/ productionresultssa11.blob.core.windows.net/ productionresultssa12.blob.core.windows.net/ productionresultssa13.blob.core.windows.net/ productionresultssa14.blob.core.windows.net/ productionresultssa15.blob.core.windows.net/ productionresultssa16.blob.core.windows.net/ productionresultssa17.blob.core.windows.net/ productionresultssa18.blob.core.windows.net/ productionresultssa19.blob.core.windows.net/ github-production-repository-image-32fea6.s3.amazonaws.com github-production-release-asset-2e65be.s3.amazonaws.com insights.github.com wss://alive.github.com; font-src github.githubassets.com; form-action 'self' github.com gist.github.com copilot-workspace.githubnext.com objects-origin.githubusercontent.com; frame-ancestors 'none'; frame-src viewscreen.githubusercontent.com notebooks.githubusercontent.com; img-src 'self' data: github.githubassets.com media.githubusercontent.com camo.githubusercontent.com identicons.github.com avatars.githubusercontent.com github-cloud.s3.amazonaws.com objects.githubusercontent.com secured-user-images.githubusercontent.com/ user-images.githubusercontent.com/ private-user-images.githubusercontent.com opengraph.githubassets.com github-production-user-asset-6210df.s3.amazonaws.com customer-stories-feed.github.com spotlights-feed.github.com objects-origin.githubusercontent.com *.githubusercontent.com; manifest-src 'self'; media-src github.com user-images.githubusercontent.com/ secured-user-images.githubusercontent.com/ private-user-images.githubusercontent.com github-production-user-asset-6210df.s3.amazonaws.com gist.github.com; script-src github.githubassets.com; style-src 'unsafe-inline' github.githubassets.com; upgrade-insecure-requests; worker-src github.com/assets-cdn/worker/ gist.github.com/assets-cdn/worker/
Set-Cookie: _gh_sess=%2Fx6rB3N4gcWuTxup89lJkPkN%2FFmPSHmmPLLJOdpB7AX75LbXnZXfwQ24Z929RDwQ4xp4RhgC8f9NtZEC4WfQkyC%2Fp%2Bl9HosNUyJKx%2BJM5680bftJdnEptw1f490VTKzAGqWyg8Dn1%2BQwa1x8A%2FFDwXw3XjpELOToZfgVQnjKUZ%2B%2BdztLZmowcks6fvh8y4xEz11oLRLKGXBdBu7Z%2BPpYY8eGAsjnum29cXWkKE0pAJDD0sFUzcrzM5qIZsBaGzSW0D%2BWZc7p9GV%2FRv8IV6vKog%3D%3D--W7jk9s3FJOKAZxq3--WbubpkrLUMdQ5S0tUziz2g%3D%3D; Path=/; HttpOnly; Secure; SameSite=Lax
Set-Cookie: _octo=GH1.1.983105413.1711835003; Path=/; Domain=github.com; Expires=Sun, 30 Mar 2025 21:43:23 GMT; Secure; SameSite=Lax
Set-Cookie: logged_in=no; Path=/; Domain=github.com; Expires=Sun, 30 Mar 2025 21:43:23 GMT; HttpOnly; Secure; SameSite=Lax
Accept-Ranges: bytes
Transfer-Encoding: chunked
X-GitHub-Request-Id: 7AB9:33DF58:8D7C76:9824F5:6608877B
connection: close

]
[2024-03-31 03:13:23,720: ERROR: main: File is not a zip file]
Traceback (most recent call last):
  File "C:\Users\rathu\Desktop\Insurance_premium-prediction\main.py", line 8, in <module>
    data_ingestion.main()
  File "c:\users\rathu\desktop\insurance_premium-prediction\src\Insurance_prediction\pipeline\stage_01_data_ingestion.py", line 17, in main
    data_ingestion.extract_zip_file()
  File "c:\users\rathu\desktop\insurance_premium-prediction\src\Insurance_prediction\components\data_ingestion.py", line 36, in extract_zip_file
    with zipfile.ZipFile(self.config.local_data_file, 'r') as zip_ref:
  File "C:\Users\rathu\anaconda3\lib\zipfile.py", line 1267, in __init__
    self._RealGetContents()
  File "C:\Users\rathu\anaconda3\lib\zipfile.py", line 1334, in _RealGetContents
    raise BadZipFile("File is not a zip file")
zipfile.BadZipFile: File is not a zip file
[2024-03-31 04:36:00,364: INFO: main: >>>>>> stage Data Ingestion stage started <<<<<<]
[2024-03-31 04:36:00,391: INFO: common: yaml file: config\config.yaml loaded successfully]
[2024-03-31 04:36:00,399: INFO: common: yaml file: params.yaml loaded successfully]
[2024-03-31 04:36:00,404: INFO: common: created directory at: artifacts]
[2024-03-31 04:36:00,406: INFO: common: created directory at: artifacts/data_ingestion]
[2024-03-31 04:36:00,413: INFO: data_ingestion: File already exists of size: ~ 143 KB]
[2024-03-31 04:36:00,490: ERROR: main: File is not a zip file]
Traceback (most recent call last):
  File "C:\Users\rathu\Desktop\Insurance_premium-prediction\main.py", line 8, in <module>
    data_ingestion.main()
  File "c:\users\rathu\desktop\insurance_premium-prediction\src\Insurance_prediction\pipeline\stage_01_data_ingestion.py", line 17, in main
    data_ingestion.extract_zip_file()
  File "c:\users\rathu\desktop\insurance_premium-prediction\src\Insurance_prediction\components\data_ingestion.py", line 36, in extract_zip_file
    with zipfile.ZipFile(self.config.local_data_file, 'r') as zip_ref:
  File "C:\Users\rathu\anaconda3\lib\zipfile.py", line 1267, in __init__
    self._RealGetContents()
  File "C:\Users\rathu\anaconda3\lib\zipfile.py", line 1334, in _RealGetContents
    raise BadZipFile("File is not a zip file")
zipfile.BadZipFile: File is not a zip file
[2024-03-31 04:45:20,182: INFO: main: >>>>>> stage Data Ingestion stage started <<<<<<]
[2024-03-31 04:45:20,202: INFO: common: yaml file: config\config.yaml loaded successfully]
[2024-03-31 04:45:20,202: INFO: common: yaml file: params.yaml loaded successfully]
[2024-03-31 04:45:20,210: INFO: common: created directory at: artifacts]
[2024-03-31 04:45:20,210: INFO: common: created directory at: artifacts/data_ingestion]
[2024-03-31 04:45:20,210: INFO: data_ingestion: File already exists of size: ~ 143 KB]
[2024-03-31 04:45:20,218: ERROR: main: File is not a zip file]
Traceback (most recent call last):
  File "C:\Users\rathu\Desktop\Insurance_premium-prediction\main.py", line 8, in <module>
    data_ingestion.main()
  File "c:\users\rathu\desktop\insurance_premium-prediction\src\Insurance_prediction\pipeline\stage_01_data_ingestion.py", line 17, in main
    data_ingestion.extract_zip_file()
  File "c:\users\rathu\desktop\insurance_premium-prediction\src\Insurance_prediction\components\data_ingestion.py", line 36, in extract_zip_file
    with zipfile.ZipFile(self.config.local_data_file, 'r') as zip_ref:
  File "C:\Users\rathu\anaconda3\lib\zipfile.py", line 1267, in __init__
    self._RealGetContents()
  File "C:\Users\rathu\anaconda3\lib\zipfile.py", line 1334, in _RealGetContents
    raise BadZipFile("File is not a zip file")
zipfile.BadZipFile: File is not a zip file
[2024-03-31 16:44:50,377: INFO: main: >>>>>> stage Data Ingestion stage started <<<<<<]
[2024-03-31 16:44:50,393: INFO: common: yaml file: config\config.yaml loaded successfully]
[2024-03-31 16:44:50,410: INFO: common: yaml file: params.yaml loaded successfully]
[2024-03-31 16:44:50,411: INFO: common: created directory at: artifacts]
[2024-03-31 16:44:50,411: INFO: common: created directory at: artifacts/data_ingestion]
[2024-03-31 16:44:50,411: INFO: data_ingestion: File already exists of size: ~ 143 KB]
[2024-03-31 17:50:09,336: INFO: main: >>>>>> stage Data Ingestion stage started <<<<<<]
[2024-03-31 17:50:09,344: INFO: common: yaml file: config\config.yaml loaded successfully]
[2024-03-31 17:50:09,344: INFO: common: yaml file: params.yaml loaded successfully]
[2024-03-31 17:50:09,344: INFO: common: created directory at: artifacts]
[2024-03-31 17:50:09,344: INFO: common: created directory at: artifacts/data_ingestion]
[2024-03-31 17:50:09,357: INFO: data_ingestion: File already exists of size: ~ 143 KB]
[2024-03-31 17:50:09,361: ERROR: main: File is not a zip file]
Traceback (most recent call last):
  File "C:\Users\rathu\Desktop\Insurance_premium-prediction\main.py", line 8, in <module>
    data_ingestion.main()
  File "c:\users\rathu\desktop\insurance_premium-prediction\src\Insurance_prediction\pipeline\stage_01_data_ingestion.py", line 17, in main
    data_ingestion.extract_zip_file()
  File "c:\users\rathu\desktop\insurance_premium-prediction\src\Insurance_prediction\components\data_ingestion.py", line 36, in extract_zip_file
    with zipfile.ZipFile(self.config.local_data_file, 'r') as zip_ref:
  File "C:\Users\rathu\anaconda3\lib\zipfile.py", line 1267, in __init__
    self._RealGetContents()
  File "C:\Users\rathu\anaconda3\lib\zipfile.py", line 1334, in _RealGetContents
    raise BadZipFile("File is not a zip file")
zipfile.BadZipFile: File is not a zip file
[2024-03-31 17:52:05,299: INFO: main: >>>>>> stage Data Ingestion stage started <<<<<<]
[2024-03-31 17:52:05,306: INFO: common: yaml file: config\config.yaml loaded successfully]
[2024-03-31 17:52:05,312: INFO: common: yaml file: params.yaml loaded successfully]
[2024-03-31 17:52:05,312: INFO: common: created directory at: artifacts]
[2024-03-31 17:52:05,312: INFO: common: created directory at: artifacts/data_ingestion]
[2024-03-31 17:52:05,312: INFO: data_ingestion: File already exists of size: ~ 143 KB]
[2024-03-31 17:52:05,318: ERROR: main: File is not a zip file]
Traceback (most recent call last):
  File "C:\Users\rathu\Desktop\Insurance_premium-prediction\main.py", line 8, in <module>
    data_ingestion.main()
  File "c:\users\rathu\desktop\insurance_premium-prediction\src\Insurance_prediction\pipeline\stage_01_data_ingestion.py", line 17, in main
    data_ingestion.extract_zip_file()
  File "c:\users\rathu\desktop\insurance_premium-prediction\src\Insurance_prediction\components\data_ingestion.py", line 36, in extract_zip_file
    with zipfile.ZipFile(self.config.local_data_file, 'r') as zip_ref:
  File "C:\Users\rathu\anaconda3\lib\zipfile.py", line 1267, in __init__
    self._RealGetContents()
  File "C:\Users\rathu\anaconda3\lib\zipfile.py", line 1334, in _RealGetContents
    raise BadZipFile("File is not a zip file")
zipfile.BadZipFile: File is not a zip file
[2024-03-31 18:01:27,646: INFO: main: >>>>>> stage Data Ingestion stage started <<<<<<]
[2024-03-31 18:01:27,656: INFO: common: yaml file: config\config.yaml loaded successfully]
[2024-03-31 18:01:27,663: INFO: common: yaml file: params.yaml loaded successfully]
[2024-03-31 18:01:27,665: INFO: common: created directory at: artifacts]
[2024-03-31 18:01:27,665: INFO: common: created directory at: artifacts/data_ingestion]
[2024-03-31 18:01:27,665: INFO: data_ingestion: File already exists of size: ~ 143 KB]
[2024-03-31 18:01:27,665: ERROR: main: File is not a zip file]
Traceback (most recent call last):
  File "C:\Users\rathu\Desktop\Insurance_premium-prediction\main.py", line 8, in <module>
    data_ingestion.main()
  File "c:\users\rathu\desktop\insurance_premium-prediction\src\Insurance_prediction\pipeline\stage_01_data_ingestion.py", line 17, in main
    data_ingestion.extract_zip_file()
  File "c:\users\rathu\desktop\insurance_premium-prediction\src\Insurance_prediction\components\data_ingestion.py", line 36, in extract_zip_file
    with zipfile.ZipFile(self.config.local_data_file, 'r') as zip_ref:
  File "C:\Users\rathu\anaconda3\lib\zipfile.py", line 1267, in __init__
    self._RealGetContents()
  File "C:\Users\rathu\anaconda3\lib\zipfile.py", line 1334, in _RealGetContents
    raise BadZipFile("File is not a zip file")
zipfile.BadZipFile: File is not a zip file
[2024-03-31 18:05:22,707: INFO: main: >>>>>> stage Data Ingestion stage started <<<<<<]
[2024-03-31 18:05:22,707: INFO: common: yaml file: config\config.yaml loaded successfully]
[2024-03-31 18:05:22,707: INFO: common: yaml file: params.yaml loaded successfully]
[2024-03-31 18:05:22,720: INFO: common: created directory at: artifacts]
[2024-03-31 18:05:22,721: INFO: common: created directory at: artifacts/data_ingestion]
[2024-03-31 18:05:22,721: INFO: data_ingestion: File already exists of size: ~ 143 KB]
[2024-03-31 18:05:22,721: ERROR: main: File is not a zip file]
Traceback (most recent call last):
  File "C:\Users\rathu\Desktop\Insurance_premium-prediction\main.py", line 8, in <module>
    data_ingestion.main()
  File "c:\users\rathu\desktop\insurance_premium-prediction\src\Insurance_prediction\pipeline\stage_01_data_ingestion.py", line 17, in main
    data_ingestion.extract_zip_file()
  File "c:\users\rathu\desktop\insurance_premium-prediction\src\Insurance_prediction\components\data_ingestion.py", line 36, in extract_zip_file
    with zipfile.ZipFile(self.config.local_data_file, 'r') as zip_ref:
  File "C:\Users\rathu\anaconda3\lib\zipfile.py", line 1267, in __init__
    self._RealGetContents()
  File "C:\Users\rathu\anaconda3\lib\zipfile.py", line 1334, in _RealGetContents
    raise BadZipFile("File is not a zip file")
zipfile.BadZipFile: File is not a zip file
[2024-03-31 18:25:58,411: INFO: main: >>>>>> stage Data Ingestion stage started <<<<<<]
[2024-03-31 18:25:58,417: INFO: common: yaml file: config\config.yaml loaded successfully]
[2024-03-31 18:25:58,419: INFO: common: yaml file: params.yaml loaded successfully]
[2024-03-31 18:25:58,419: INFO: common: created directory at: artifacts]
[2024-03-31 18:25:58,419: INFO: common: created directory at: artifacts/data_ingestion]
[2024-03-31 18:25:58,427: INFO: data_ingestion: File already exists of size: ~ 143 KB]
[2024-03-31 18:25:58,427: ERROR: main: File is not a zip file]
Traceback (most recent call last):
  File "C:\Users\rathu\Desktop\Insurance_premium-prediction\main.py", line 8, in <module>
    data_ingestion.main()
  File "c:\users\rathu\desktop\insurance_premium-prediction\src\Insurance_prediction\pipeline\stage_01_data_ingestion.py", line 17, in main
    data_ingestion.extract_zip_file()
  File "c:\users\rathu\desktop\insurance_premium-prediction\src\Insurance_prediction\components\data_ingestion.py", line 36, in extract_zip_file
    with zipfile.ZipFile(self.config.local_data_file, 'r') as zip_ref:
  File "C:\Users\rathu\anaconda3\lib\zipfile.py", line 1267, in __init__
    self._RealGetContents()
  File "C:\Users\rathu\anaconda3\lib\zipfile.py", line 1334, in _RealGetContents
    raise BadZipFile("File is not a zip file")
zipfile.BadZipFile: File is not a zip file
[2024-03-31 18:27:04,383: INFO: main: >>>>>> stage Data Ingestion stage started <<<<<<]
[2024-03-31 18:27:04,388: INFO: common: yaml file: config\config.yaml loaded successfully]
[2024-03-31 18:27:04,388: INFO: common: yaml file: params.yaml loaded successfully]
[2024-03-31 18:27:04,388: INFO: common: created directory at: artifacts]
[2024-03-31 18:27:04,396: INFO: common: created directory at: artifacts/data_ingestion]
[2024-03-31 18:27:04,399: INFO: data_ingestion: File already exists of size: ~ 143 KB]
[2024-03-31 18:27:04,401: ERROR: main: File is not a zip file]
Traceback (most recent call last):
  File "C:\Users\rathu\Desktop\Insurance_premium-prediction\main.py", line 8, in <module>
    data_ingestion.main()
  File "c:\users\rathu\desktop\insurance_premium-prediction\src\Insurance_prediction\pipeline\stage_01_data_ingestion.py", line 17, in main
    data_ingestion.extract_zip_file()
  File "c:\users\rathu\desktop\insurance_premium-prediction\src\Insurance_prediction\components\data_ingestion.py", line 36, in extract_zip_file
    with zipfile.ZipFile(self.config.local_data_file, 'r') as zip_ref:
  File "C:\Users\rathu\anaconda3\lib\zipfile.py", line 1267, in __init__
    self._RealGetContents()
  File "C:\Users\rathu\anaconda3\lib\zipfile.py", line 1334, in _RealGetContents
    raise BadZipFile("File is not a zip file")
zipfile.BadZipFile: File is not a zip file
[2024-04-01 18:23:43,474: INFO: main: >>>>>> stage Data Ingestion stage started <<<<<<]
[2024-04-01 18:23:43,483: INFO: common: yaml file: config\config.yaml loaded successfully]
[2024-04-01 18:23:43,497: INFO: common: yaml file: params.yaml loaded successfully]
[2024-04-01 18:23:43,497: INFO: common: created directory at: artifacts]
[2024-04-01 18:23:43,500: INFO: common: created directory at: artifacts/data_ingestion]
[2024-04-01 18:23:43,500: INFO: data_ingestion: File already exists of size: ~ 143 KB]
[2024-04-01 18:23:43,567: ERROR: main: File is not a zip file]
Traceback (most recent call last):
  File "C:\Users\rathu\Desktop\Insurance_premium-prediction\main.py", line 8, in <module>
    data_ingestion.main()
  File "c:\users\rathu\desktop\insurance_premium-prediction\src\Insurance_prediction\pipeline\stage_01_data_ingestion.py", line 17, in main
    data_ingestion.extract_zip_file()
  File "c:\users\rathu\desktop\insurance_premium-prediction\src\Insurance_prediction\components\data_ingestion.py", line 36, in extract_zip_file
    with zipfile.ZipFile(self.config.local_data_file, 'r') as zip_ref:
  File "C:\Users\rathu\anaconda3\lib\zipfile.py", line 1267, in __init__
    self._RealGetContents()
  File "C:\Users\rathu\anaconda3\lib\zipfile.py", line 1334, in _RealGetContents
    raise BadZipFile("File is not a zip file")
zipfile.BadZipFile: File is not a zip file
